<mujoco>
	<body childclass="robot0:fetch" name="robot0:base" pos="0 0 1">
		<geom size="0.1 0.05 0.05" type="box" mass="0.002" material="table_mat"></geom>
		<body name="robot0:link0" pos="0.1475 0 0">
			<geom size="0.005 0.047" euler="0 90 0" type="cylinder" material="robot0:arm_mat" mass="0.1" class="robot0:blue"></geom>
			<body name="robot0:middle0" pos="0.0525 0 0">
				<geom size="0.004 0.004 0.004" type="sphere" material="robot0:arm_mat" mass="0.1"></geom>
				<joint axis="0 0 1"  pos="0 0 0" name="robot0:joint1" range="-90 90"></joint>
				<body name="robot0:link1" pos="0.05 0 0">
					<geom size="0.005 0.045" euler="0 90 0" type="cylinder" material="robot0:arm_mat" mass="0.1"></geom>
					<joint axis="0 1 0"  pos="-0.05 0 0" name="robot0:joint2" range="-90 90"></joint>
					<body name="robot0:middle1" pos="0.05 0 0">
						<geom size="0.004 0.004 0.004" type="sphere" material="robot0:arm_mat"></geom>
						<joint axis="0 0 1"  pos="0 0 0" name="robot0:joint3" range="-90 90"></joint>
						<body name="robot0:link2" pos="0.05 0 0">
							<geom size="0.005 0.045" euler="0 90 0" type="cylinder" material="robot0:arm_mat" mass="0.1" class="robot0:blue"></geom>
							<joint axis="0 1 0"  pos="-0.05 0 0" name="robot0:joint4" range="-90 90"></joint>
							<body name="robot0:middle2" pos="0.05 0 0">
								<geom size="0.004 0.004 0.004" type="sphere" material="robot0:arm_mat" mass="0.1"></geom>
								<joint axis="0 0 1"  pos="0 0 0" name="robot0:joint5" range="-90 90"></joint>
								<body name="robot0:link3" pos="0.05 0 0">
									<geom size="0.005 0.045" euler="0 90 0" type="cylinder" material="robot0:arm_mat" mass="0.1"></geom>
									<joint axis="0 1 0"  pos="-0.05 0 0" name="robot0:joint6" range="-90 90"></joint>
									<body name="robot0:middle3" pos="0.05 0 0">
										<geom size="0.004 0.004 0.004" type="sphere" material="robot0:arm_mat" mass="0.1"></geom>
										<joint axis="0 0 1"  pos="0 0 0" name="robot0:joint7" range="-90 90"></joint>
										<body name="robot0:link4" pos="0.05 0 0">
											<geom size="0.005 0.045" euler="0 90 0" type="cylinder" material="robot0:arm_mat" mass="0.1" class="robot0:blue"></geom>
											<joint axis="0 1 0"  pos="-0.05 0 0" name="robot0:joint8" range="-90 90"></joint>
											<body name="robot0:middle4" pos="0.05 0 0">
												<geom  size="0.004 0.004 0.004" type="sphere" material="robot0:arm_mat" mass="0.1" class="robot0:yellow"></geom>
												<site name="robot0:tip" pos="0 0 0" rgba="0 0 0 0" size="0.004 0.004 0.004"></site>
											</body>
										</body>
									</body>
								</body>
							</body>
						</body>
					</body>
				</body>
			</body>
		</body>
	</body>
</mujoco>
